<?xml version="1.0"?>
<robot xmlns:xacro="http://www.ros.org/wiki/xacro">

  <!-- Macro for wheel -->
  <xacro:macro name="wheel" params="link_name wheel_pos mesh_filename">
    <link name="${link_name}">
      <xacro:inertia_cylinder mass="${wheel_mass}" r="${wheel_radius}" l="${wheel_thickness}" xyz="0 0 0" rpy="0 1.571 1.571"/>
      <collision>
        <origin rpy="0 1.571 1.571" xyz="0 0 0"/>
        <geometry>
          <cylinder length="${wheel_thickness}" radius="${wheel_radius}"/>
        </geometry>
      </collision>

      <visual>
        <origin rpy="0 0 0" xyz="0 0 0"/>
        <geometry>
          <mesh filename="package://general_description/meshes/${mesh_filename}" scale="1 1 1"/>
        </geometry>
        <material name="wheel"/>
      </visual>
    </link>

    <!-- Joint btw wheel and base -->
    <joint name="${link_name}_joint" type="continuous">
      <origin rpy="0 0 0" xyz="${wheel_pos}"/>
      <child link="${link_name}"/>
      <parent link="base_link"/>
      <axis rpy="0 0 0" xyz="0 1 0"/>
      <limit effort="100" velocity="100"/>
      <joint_properties damping="0.0" friction="0.0"/>
    </joint>

    <transmission name="${link_name}_joint_trans}" type="SimpleTransmission">
			<type>transmission_interface/SimpleTransmission</type>
			<actuator name="${link_name}_joint_motor">
				<mechanicalReduction>1.0</mechanicalReduction>
			</actuator>
			<joint name="${link_name}_joint">
				<hardwareInterface>hardware_interface/VelocityJointInterface</hardwareInterface>
			</joint>
		</transmission>

    <gazebo reference="${link_name}" >
      <mu1 value="1.0" />
      <mu2 value="1.0" />
      <kp  value="100000.0" />
      <kd  value="1.0" />
    </gazebo>

  </xacro:macro>

</robot>